Traceback (most recent call last):
  File "/usr/share/miniconda/envs/open-machine-learning-jupyter-book/lib/python3.9/site-packages/jupyter_cache/executors/utils.py", line 51, in single_nb_execution
    executenb(
  File "/usr/share/miniconda/envs/open-machine-learning-jupyter-book/lib/python3.9/site-packages/nbclient/client.py", line 1204, in execute
    return NotebookClient(nb=nb, resources=resources, km=km, **kwargs).execute()
  File "/usr/share/miniconda/envs/open-machine-learning-jupyter-book/lib/python3.9/site-packages/nbclient/util.py", line 84, in wrapped
    return just_run(coro(*args, **kwargs))
  File "/usr/share/miniconda/envs/open-machine-learning-jupyter-book/lib/python3.9/site-packages/nbclient/util.py", line 62, in just_run
    return loop.run_until_complete(coro)
  File "/usr/share/miniconda/envs/open-machine-learning-jupyter-book/lib/python3.9/asyncio/base_events.py", line 647, in run_until_complete
    return future.result()
  File "/usr/share/miniconda/envs/open-machine-learning-jupyter-book/lib/python3.9/site-packages/nbclient/client.py", line 663, in async_execute
    await self.async_execute_cell(
  File "/usr/share/miniconda/envs/open-machine-learning-jupyter-book/lib/python3.9/site-packages/nbclient/client.py", line 965, in async_execute_cell
    await self._check_raise_for_error(cell, cell_index, exec_reply)
  File "/usr/share/miniconda/envs/open-machine-learning-jupyter-book/lib/python3.9/site-packages/nbclient/client.py", line 862, in _check_raise_for_error
    raise CellExecutionError.from_cell_and_msg(cell, exec_reply_content)
nbclient.exceptions.CellExecutionError: An error occurred while executing the following cell:
------------------
from sklearn import linear_model

# Fit the model
exam_model = linear_model.LinearRegression(normalize=True)
x = np.expand_dims(num_hours_studied, 1)
y = exam_score
exam_model.fit(x, y)
a = exam_model.coef_
b = exam_model.intercept_
print(exam_model.coef_)
print(exam_model.intercept_)
------------------

[0;31m---------------------------------------------------------------------------[0m
[0;31mTypeError[0m                                 Traceback (most recent call last)
Cell [0;32mIn[3], line 4[0m
[1;32m      1[0m [38;5;28;01mfrom[39;00m [38;5;21;01msklearn[39;00m [38;5;28;01mimport[39;00m linear_model
[1;32m      3[0m [38;5;66;03m# Fit the model[39;00m
[0;32m----> 4[0m exam_model [38;5;241m=[39m [43mlinear_model[49m[38;5;241;43m.[39;49m[43mLinearRegression[49m[43m([49m[43mnormalize[49m[38;5;241;43m=[39;49m[38;5;28;43;01mTrue[39;49;00m[43m)[49m
[1;32m      5[0m x [38;5;241m=[39m np[38;5;241m.[39mexpand_dims(num_hours_studied, [38;5;241m1[39m)
[1;32m      6[0m y [38;5;241m=[39m exam_score

[0;31mTypeError[0m: __init__() got an unexpected keyword argument 'normalize'
TypeError: __init__() got an unexpected keyword argument 'normalize'

