Traceback (most recent call last):
  File "/usr/share/miniconda/envs/open-machine-learning-jupyter-book/lib/python3.9/site-packages/jupyter_cache/executors/utils.py", line 51, in single_nb_execution
    executenb(
  File "/usr/share/miniconda/envs/open-machine-learning-jupyter-book/lib/python3.9/site-packages/nbclient/client.py", line 1204, in execute
    return NotebookClient(nb=nb, resources=resources, km=km, **kwargs).execute()
  File "/usr/share/miniconda/envs/open-machine-learning-jupyter-book/lib/python3.9/site-packages/nbclient/util.py", line 84, in wrapped
    return just_run(coro(*args, **kwargs))
  File "/usr/share/miniconda/envs/open-machine-learning-jupyter-book/lib/python3.9/site-packages/nbclient/util.py", line 62, in just_run
    return loop.run_until_complete(coro)
  File "/usr/share/miniconda/envs/open-machine-learning-jupyter-book/lib/python3.9/asyncio/base_events.py", line 647, in run_until_complete
    return future.result()
  File "/usr/share/miniconda/envs/open-machine-learning-jupyter-book/lib/python3.9/site-packages/nbclient/client.py", line 663, in async_execute
    await self.async_execute_cell(
  File "/usr/share/miniconda/envs/open-machine-learning-jupyter-book/lib/python3.9/site-packages/nbclient/client.py", line 965, in async_execute_cell
    await self._check_raise_for_error(cell, cell_index, exec_reply)
  File "/usr/share/miniconda/envs/open-machine-learning-jupyter-book/lib/python3.9/site-packages/nbclient/client.py", line 862, in _check_raise_for_error
    raise CellExecutionError.from_cell_and_msg(cell, exec_reply_content)
nbclient.exceptions.CellExecutionError: An error occurred while executing the following cell:
------------------
import numpy as np
import pandas as pd
import seaborn as sns
titanic = sns.load_dataset('../../assets/data/titanic')
------------------

[0;31m---------------------------------------------------------------------------[0m
[0;31mValueError[0m                                Traceback (most recent call last)
Cell [0;32mIn [239], line 4[0m
[1;32m      2[0m [38;5;28;01mimport[39;00m [38;5;21;01mpandas[39;00m [38;5;28;01mas[39;00m [38;5;21;01mpd[39;00m
[1;32m      3[0m [38;5;28;01mimport[39;00m [38;5;21;01mseaborn[39;00m [38;5;28;01mas[39;00m [38;5;21;01msns[39;00m
[0;32m----> 4[0m titanic [38;5;241m=[39m [43msns[49m[38;5;241;43m.[39;49m[43mload_dataset[49m[43m([49m[38;5;124;43m'[39;49m[38;5;124;43m../../assets/data/titanic[39;49m[38;5;124;43m'[39;49m[43m)[49m

File [0;32m/usr/share/miniconda/envs/open-machine-learning-jupyter-book/lib/python3.9/site-packages/seaborn/utils.py:583[0m, in [0;36mload_dataset[0;34m(name, cache, data_home, **kws)[0m
[1;32m    581[0m [38;5;28;01mif[39;00m [38;5;129;01mnot[39;00m os[38;5;241m.[39mpath[38;5;241m.[39mexists(cache_path):
[1;32m    582[0m     [38;5;28;01mif[39;00m name [38;5;129;01mnot[39;00m [38;5;129;01min[39;00m get_dataset_names():
[0;32m--> 583[0m         [38;5;28;01mraise[39;00m [38;5;167;01mValueError[39;00m([38;5;124mf[39m[38;5;124m"[39m[38;5;124m'[39m[38;5;132;01m{[39;00mname[38;5;132;01m}[39;00m[38;5;124m'[39m[38;5;124m is not one of the example datasets.[39m[38;5;124m"[39m)
[1;32m    584[0m     urlretrieve(url, cache_path)
[1;32m    585[0m full_path [38;5;241m=[39m cache_path

[0;31mValueError[0m: '../../assets/data/titanic' is not one of the example datasets.
ValueError: '../../assets/data/titanic' is not one of the example datasets.

